Workbook

Sheet Dados gerais
A2: Ano | B2: Data | C2: Mês | D2: M2 | E2: Qte C | G2: Ano | H2: Data | I2: Mês | J2: M2 | K2: Qte C | M2: Ano | N2: Data | O2: Mês | P2: M2 | Q2: Qte C | S2: Ano | T2: Data | U2: Mês | V2: M2 | W2: Qte C | Y2: Ano | Z2: Data | AA2: Mês | AB2: M2 | AC2: Qte C
A3: 2021 | B3: 44197 | C3: =TEXT(B3,"mmmm") -> janeiro | D3: 3041 | E3: 200 | G3: 2022 | H3: 44562 | I3: janeiro | J3: 3041 | K3: 222 | M3: 2023 | N3: 44927 | O3: janeiro | P3: 3041 | Q3: 236 | S3: 2024 | T3: 45292 | U3: janeiro | V3: 3041 | W3: 250 | Y3: 2025 | Z3: 45658 | AA3: janeiro | AB3: 3041 | AC3: 287
A4: 2021 | B4: 44228 | C4: =TEXT(B4,"mmmm") -> fevereiro | D4: 3041 | E4: 200 | G4: 2022 | H4: 44593 | I4: fevereiro | J4: 3041 | K4: 220 | M4: 2023 | N4: 44958 | O4: fevereiro | P4: 3041 | Q4: 230 | S4: 2024 | T4: 45323 | U4: fevereiro | V4: 3041 | W4: 249 | Y4: 2025 | Z4: 45689 | AA4: fevereiro | AB4: 3041 | AC4: 294
A5: 2021 | B5: 44256 | C5: =TEXT(B5,"mmmm") -> março | D5: 3041 | E5: 201 | G5: 2022 | H5: 44621 | I5: março | J5: 3041 | K5: 221 | M5: 2023 | N5: 44986 | O5: março | P5: 3041 | Q5: 234 | S5: 2024 | T5: 45352 | U5: março | V5: 3041 | W5: 250 | Y5: 2025 | Z5: 45717 | AA5: março | AB5: 3041 | AC5: 294
A6: 2021 | B6: =B5+31 -> 44287 | C6: =TEXT(B6,"mmmm") -> abril | D6: 3041 | E6: 204 | G6: 2022 | H6: 44652 | I6: abril | J6: 3041 | K6: 232 | M6: 2023 | N6: 45017 | O6: abril | P6: 3041 | Q6: 236 | S6: 2024 | T6: 45383 | U6: abril | V6: 3041 | W6: 259 | Y6: 2025 | Z6: 45748 | AA6: abril
A7: 2021 | B7: 44317 | C7: =TEXT(B7,"mmmm") -> maio | D7: 3041 | E7: 199 | G7: 2022 | H7: 44682 | I7: maio | J7: 3041 | K7: 227 | M7: 2023 | N7: 45047 | O7: maio | P7: 3041 | Q7: 237 | S7: 2024 | T7: 45413 | U7: maio | V7: 3041 | W7: 257 | Y7: 2025 | Z7: 45778 | AA7: maio
A8: 2021 | B8: =B7+31 -> 44348 | C8: =TEXT(B8,"mmmm") -> junho | D8: 3041 | E8: 208 | G8: 2022 | H8: 44713 | I8: junho | J8: 3041 | K8: 229 | M8: 2023 | N8: 45078 | O8: junho | P8: 3041 | Q8: 239 | S8: 2024 | T8: 45444 | U8: junho | V8: 3041 | W8: 255 | Y8: 2025 | Z8: 45809 | AA8: junho
A9: 2021 | B9: 44378 | C9: =TEXT(B9,"mmmm") -> julho | D9: 3041 | E9: 209 | G9: 2022 | H9: 44743 | I9: julho | J9: 3041 | K9: 234 | M9: 2023 | N9: 45108 | O9: julho | P9: 3041 | Q9: 248 | S9: 2024 | T9: 45474 | U9: julho | V9: 3041 | W9: 262 | Y9: 2025 | Z9: 45839 | AA9: julho
A10: 2021 | B10: =B9+31 -> 44409 | C10: =TEXT(B10,"mmmm") -> agosto | D10: 3041 | E10: 203 | G10: 2022 | H10: 44774 | I10: agosto | J10: 3041 | K10: 229 | M10: 2023 | N10: 45139 | O10: agosto | P10: 3041 | Q10: 248 | S10: 2024 | T10: 45505 | U10: agosto | V10: 3041 | W10: 258 | Y10: 2025 | Z10: 45870 | AA10: agosto
A11: 2021 | B11: =B10+31 -> 44440 | C11: =TEXT(B11,"mmmm") -> setembro | D11: 3041 | E11: 211 | G11: 2022 | H11: 44805 | I11: setembro | J11: 3041 | K11: 231 | M11: 2023 | N11: 45170 | O11: setembro | P11: 3041 | Q11: 248 | S11: 2024 | T11: 45536 | U11: setembro | V11: 3041 | W11: 258 | Y11: 2025 | Z11: 45901 | AA11: setembro
A12: 2021 | B12: 44470 | C12: =TEXT(B12,"mmmm") -> outubro | D12: 3041 | E12: 219 | G12: 2022 | H12: 44835 | I12: outubro | J12: 3041 | K12: 231 | M12: 2023 | N12: 45200 | O12: outubro | P12: 3041 | Q12: 247 | S12: 2024 | T12: 45566 | U12: outubro | V12: 3041 | W12: 264 | Y12: 2025 | Z12: 45931 | AA12: outubro
A13: 2021 | B13: =B12+31 -> 44501 | C13: =TEXT(B13,"mmmm") -> novembro | D13: 3041 | E13: 219 | G13: 2022 | H13: 44866 | I13: novembro | J13: 3041 | K13: 234 | M13: 2023 | N13: 45231 | O13: novembro | P13: 3041 | Q13: 246 | S13: 2024 | T13: 45597 | U13: novembro | V13: 3041 | W13: 266 | Y13: 2025 | Z13: 45962 | AA13: novembro
A14: 2021 | B14: 44531 | C14: =TEXT(B14,"mmmm") -> dezembro | D14: 3041 | E14: 220 | G14: 2022 | H14: 44896 | I14: dezembro | J14: 3041 | K14: 237 | M14: 2023 | N14: 45261 | O14: dezembro | P14: 3041 | Q14: 243 | S14: 2024 | T14: 45627 | U14: dezembro | V14: 3041 | W14: 278 | Y14: 2025 | Z14: 45992 | AA14: dezembro
E15: =SUM(E3:E14) -> 2493 | K15: =SUM(K3:K14) -> 2747 | Q15: =SUM(Q3:Q14) -> 2892 | W15: =SUM(W3:W14) -> 3106 | AC15: =SUM(AC3:AC14) -> 875

Sheet Água
A1: Ano | B1: Nome do mês | C1: Mês | D1: Consumo em litros | E1: Qte colaboradores | F1: Qte metros quadrados | G1: Qte litros agua por colaborador | H1: Qte litros de agua por metro quadrado
A2: 2021 | B2: ='Dados gerais'!B3 -> 44197 | C2: =TEXT(B2,"mmmm") -> janeiro | D2: =RANDBETWEEN(181200,344400) -> 299308 | E2: ='Dados gerais'!E3 -> 200 | F2: ='Dados gerais'!D3 -> 3041 | G2: =D2/E2 -> 1496.54 | H2: =D2/F2 -> 98.424203
A3: 2021 | B3: ='Dados gerais'!B4 -> 44228 | C3: =TEXT(B3,"mmmm") -> fevereiro | D3: =RANDBETWEEN(181200,344400) -> 299534 | E3: ='Dados gerais'!E4 -> 200 | F3: ='Dados gerais'!D4 -> 3041 | G3: =D3/E3 -> 1497.67 | H3: =D3/F3 -> 98.49852 | Y3: É o mês da Referência = 03/2024
A4: 2021 | B4: ='Dados gerais'!B5 -> 44256 | C4: =TEXT(B4,"mmmm") -> março | D4: =RANDBETWEEN(181200,344400) -> 188175 | E4: ='Dados gerais'!E5 -> 201 | F4: ='Dados gerais'!D5 -> 3041 | G4: =D4/E4 -> 936.19403 | H4: =D4/F4 -> 61.879316
A5: 2021 | B5: ='Dados gerais'!B6 -> 44287 | C5: =TEXT(B5,"mmmm") -> abril | D5: =RANDBETWEEN(181200,344400) -> 260829 | E5: ='Dados gerais'!E6 -> 204 | F5: ='Dados gerais'!D6 -> 3041 | G5: =D5/E5 -> 1278.5735 | H5: =D5/F5 -> 85.770799
A6: 2021 | B6: ='Dados gerais'!B7 -> 44317 | C6: =TEXT(B6,"mmmm") -> maio | D6: =RANDBETWEEN(181200,344400) -> 273071 | E6: ='Dados gerais'!E7 -> 199 | F6: ='Dados gerais'!D7 -> 3041 | G6: =D6/E6 -> 1372.2161 | H6: =D6/F6 -> 89.796449
A7: 2021 | B7: ='Dados gerais'!B8 -> 44348 | C7: =TEXT(B7,"mmmm") -> junho | D7: =RANDBETWEEN(181200,344400) -> 199651 | E7: ='Dados gerais'!E8 -> 208 | F7: ='Dados gerais'!D8 -> 3041 | G7: =D7/E7 -> 959.86058 | H7: =D7/F7 -> 65.653075
A8: 2021 | B8: ='Dados gerais'!B9 -> 44378 | C8: =TEXT(B8,"mmmm") -> julho | D8: =RANDBETWEEN(181200,344400) -> 315368 | E8: ='Dados gerais'!E9 -> 209 | F8: ='Dados gerais'!D9 -> 3041 | G8: =D8/E8 -> 1508.9378 | H8: =D8/F8 -> 103.70536
A9: 2021 | B9: ='Dados gerais'!B10 -> 44409 | C9: =TEXT(B9,"mmmm") -> agosto | D9: =RANDBETWEEN(181200,344400) -> 236318 | E9: ='Dados gerais'!E10 -> 203 | F9: ='Dados gerais'!D10 -> 3041 | G9: =D9/E9 -> 1164.1281 | H9: =D9/F9 -> 77.710622
A10: 2021 | B10: ='Dados gerais'!B11 -> 44440 | C10: =TEXT(B10,"mmmm") -> setembro | D10: =RANDBETWEEN(181200,344400) -> 236322 | E10: ='Dados gerais'!E11 -> 211 | F10: ='Dados gerais'!D11 -> 3041 | G10: =D10/E10 -> 1120.0095 | H10: =D10/F10 -> 77.711937
A11: 2021 | B11: ='Dados gerais'!B12 -> 44470 | C11: =TEXT(B11,"mmmm") -> outubro | D11: =RANDBETWEEN(181200,344400) -> 337023 | E11: ='Dados gerais'!E12 -> 219 | F11: ='Dados gerais'!D12 -> 3041 | G11: =D11/E11 -> 1538.9178 | H11: =D11/F11 -> 110.82637
A12: 2021 | B12: ='Dados gerais'!B13 -> 44501 | C12: =TEXT(B12,"mmmm") -> novembro | D12: =RANDBETWEEN(181200,344400) -> 211010 | E12: ='Dados gerais'!E13 -> 219 | F12: ='Dados gerais'!D13 -> 3041 | G12: =D12/E12 -> 963.51598 | H12: =D12/F12 -> 69.388359
A13: 2021 | B13: ='Dados gerais'!B14 -> 44531 | C13: =TEXT(B13,"mmmm") -> dezembro | D13: =RANDBETWEEN(181200,344400) -> 266727 | E13: ='Dados gerais'!E14 -> 220 | F13: ='Dados gerais'!D14 -> 3041 | G13: =D13/E13 -> 1212.3955 | H13: =D13/F13 -> 87.710293
A14: 2022 | B14: ='Dados gerais'!H3 -> 44562 | C14: =TEXT(B14,"mmmm") -> janeiro | D14: =RANDBETWEEN(181200,344400) -> 318184 | E14: ='Dados gerais'!K3 -> 222 | F14: ='Dados gerais'!J3 -> 3041 | G14: =D14/E14 -> 1433.2613 | H14: =D14/F14 -> 104.63137
A15: 2022 | B15: ='Dados gerais'!H4 -> 44593 | C15: =TEXT(B15,"mmmm") -> fevereiro | D15: =RANDBETWEEN(181200,344400) -> 316068 | E15: ='Dados gerais'!K4 -> 220 | F15: ='Dados gerais'!J4 -> 3041 | G15: =D15/E15 -> 1436.6727 | H15: =D15/F15 -> 103.93555
A16: 2022 | B16: ='Dados gerais'!H5 -> 44621 | C16: =TEXT(B16,"mmmm") -> março | D16: =RANDBETWEEN(181200,344400) -> 328691 | E16: ='Dados gerais'!K5 -> 221 | F16: ='Dados gerais'!J5 -> 3041 | G16: =D16/E16 -> 1487.2896 | H16: =D16/F16 -> 108.08648
A17: 2022 | B17: ='Dados gerais'!H6 -> 44652 | C17: =TEXT(B17,"mmmm") -> abril | D17: =RANDBETWEEN(181200,344400) -> 276961 | E17: ='Dados gerais'!K6 -> 232 | F17: ='Dados gerais'!J6 -> 3041 | G17: =D17/E17 -> 1193.7974 | H17: =D17/F17 -> 91.075633
A18: 2022 | B18: ='Dados gerais'!H7 -> 44682 | C18: =TEXT(B18,"mmmm") -> maio | D18: =RANDBETWEEN(181200,344400) -> 199159 | E18: ='Dados gerais'!K7 -> 227 | F18: ='Dados gerais'!J7 -> 3041 | G18: =D18/E18 -> 877.35242 | H18: =D18/F18 -> 65.491286
A19: 2022 | B19: ='Dados gerais'!H8 -> 44713 | C19: =TEXT(B19,"mmmm") -> junho | D19: =RANDBETWEEN(181200,344400) -> 259355 | E19: ='Dados gerais'!K8 -> 229 | F19: ='Dados gerais'!J8 -> 3041 | G19: =D19/E19 -> 1132.5546 | H19: =D19/F19 -> 85.28609
A20: 2022 | B20: ='Dados gerais'!H9 -> 44743 | C20: =TEXT(B20,"mmmm") -> julho | D20: =RANDBETWEEN(181200,344400) -> 182448 | E20: ='Dados gerais'!K9 -> 234 | F20: ='Dados gerais'!J9 -> 3041 | G20: =D20/E20 -> 779.69231 | H20: =D20/F20 -> 59.996054
A21: 2022 | B21: ='Dados gerais'!H10 -> 44774 | C21: =TEXT(B21,"mmmm") -> agosto | D21: =RANDBETWEEN(181200,344400) -> 245444 | E21: ='Dados gerais'!K10 -> 229 | F21: ='Dados gerais'!J10 -> 3041 | G21: =D21/E21 -> 1071.8079 | H21: =D21/F21 -> 80.711608
A22: 2022 | B22: ='Dados gerais'!H11 -> 44805 | C22: =TEXT(B22,"mmmm") -> setembro | D22: =RANDBETWEEN(181200,344400) -> 327455 | E22: ='Dados gerais'!K11 -> 231 | F22: ='Dados gerais'!J11 -> 3041 | G22: =D22/E22 -> 1417.5541 | H22: =D22/F22 -> 107.68004
A23: 2022 | B23: ='Dados gerais'!H12 -> 44835 | C23: =TEXT(B23,"mmmm") -> outubro | D23: =RANDBETWEEN(181200,344400) -> 254444 | E23: ='Dados gerais'!K12 -> 231 | F23: ='Dados gerais'!J12 -> 3041 | G23: =D23/E23 -> 1101.4892 | H23: =D23/F23 -> 83.671161
A24: 2022 | B24: ='Dados gerais'!H13 -> 44866 | C24: =TEXT(B24,"mmmm") -> novembro | D24: =RANDBETWEEN(181200,344400) -> 244912 | E24: ='Dados gerais'!K13 -> 234 | F24: ='Dados gerais'!J13 -> 3041 | G24: =D24/E24 -> 1046.6325 | H24: =D24/F24 -> 80.536666
A25: 2022 | B25: ='Dados gerais'!H14 -> 44896 | C25: =TEXT(B25,"mmmm") -> dezembro | D25: =RANDBETWEEN(181200,344400) -> 307533 | E25: ='Dados gerais'!K14 -> 237 | F25: ='Dados gerais'!J14 -> 3041 | G25: =D25/E25 -> 1297.6076 | H25: =D25/F25 -> 101.1289
A26: 2023 | B26: ='Dados gerais'!N3 -> 44927 | C26: =TEXT(B26,"mmmm") -> janeiro | D26: =RANDBETWEEN(181200,344400) -> 313985 | E26: ='Dados gerais'!Q3 -> 236 | F26: ='Dados gerais'!P3 -> 3041 | G26: =D26/E26 -> 1330.4449 | H26: =D26/F26 -> 103.25058
A27: 2023 | B27: ='Dados gerais'!N4 -> 44958 | C27: =TEXT(B27,"mmmm") -> fevereiro | D27: =RANDBETWEEN(181200,344400) -> 183532 | E27: ='Dados gerais'!Q4 -> 230 | F27: ='Dados gerais'!P4 -> 3041 | G27: =D27/E27 -> 797.96522 | H27: =D27/F27 -> 60.352516
A28: 2023 | B28: ='Dados gerais'!N5 -> 44986 | C28: =TEXT(B28,"mmmm") -> março | D28: =RANDBETWEEN(181200,344400) -> 199335 | E28: ='Dados gerais'!Q5 -> 234 | F28: ='Dados gerais'!P5 -> 3041 | G28: =D28/E28 -> 851.85897 | H28: =D28/F28 -> 65.549161
A29: 2023 | B29: ='Dados gerais'!N6 -> 45017 | C29: =TEXT(B29,"mmmm") -> abril | D29: =RANDBETWEEN(181200,344400) -> 247089 | E29: ='Dados gerais'!Q6 -> 236 | F29: ='Dados gerais'!P6 -> 3041 | G29: =D29/E29 -> 1046.9873 | H29: =D29/F29 -> 81.252549
A30: 2023 | B30: ='Dados gerais'!N7 -> 45047 | C30: =TEXT(B30,"mmmm") -> maio | D30: =RANDBETWEEN(181200,344400) -> 286131 | E30: ='Dados gerais'!Q7 -> 237 | F30: ='Dados gerais'!P7 -> 3041 | G30: =D30/E30 -> 1207.3038 | H30: =D30/F30 -> 94.091088
A31: 2023 | B31: ='Dados gerais'!N8 -> 45078 | C31: =TEXT(B31,"mmmm") -> junho | D31: =RANDBETWEEN(181200,344400) -> 264388 | E31: ='Dados gerais'!Q8 -> 239 | F31: ='Dados gerais'!P8 -> 3041 | G31: =D31/E31 -> 1106.2259 | H31: =D31/F31 -> 86.941138
A32: 2023 | B32: ='Dados gerais'!N9 -> 45108 | C32: julho | D32: =RANDBETWEEN(181200,344400) -> 270982 | E32: ='Dados gerais'!Q9 -> 248 | F32: ='Dados gerais'!P9 -> 3041 | G32: =D32/E32 -> 1092.6694 | H32: =D32/F32 -> 89.109503
A33: 2023 | B33: ='Dados gerais'!N10 -> 45139 | C33: agosto | D33: =RANDBETWEEN(181200,344400) -> 276442 | E33: ='Dados gerais'!Q10 -> 248 | F33: ='Dados gerais'!P10 -> 3041 | G33: =D33/E33 -> 1114.6855 | H33: =D33/F33 -> 90.904965
A34: 2023 | B34: ='Dados gerais'!N11 -> 45170 | C34: setembro | D34: =RANDBETWEEN(181200,344400) -> 260465 | E34: ='Dados gerais'!Q11 -> 248 | F34: ='Dados gerais'!P11 -> 3041 | G34: =D34/E34 -> 1050.2621 | H34: =D34/F34 -> 85.651102
A35: 2023 | B35: ='Dados gerais'!N12 -> 45200 | C35: outubro | D35: =RANDBETWEEN(181200,344400) -> 305733 | E35: ='Dados gerais'!Q12 -> 247 | F35: ='Dados gerais'!P12 -> 3041 | G35: =D35/E35 -> 1237.7854 | H35: =D35/F35 -> 100.53699
A36: 2023 | B36: ='Dados gerais'!N13 -> 45231 | C36: novembro | D36: =RANDBETWEEN(181200,344400) -> 215073 | E36: ='Dados gerais'!Q13 -> 246 | F36: ='Dados gerais'!P13 -> 3041 | G36: =D36/E36 -> 874.28049 | H36: =D36/F36 -> 70.724433
A37: 2023 | B37: ='Dados gerais'!N14 -> 45261 | C37: dezembro | D37: =RANDBETWEEN(181200,344400) -> 262862 | E37: ='Dados gerais'!Q14 -> 243 | F37: ='Dados gerais'!P14 -> 3041 | G37: =D37/E37 -> 1081.7366 | H37: =D37/F37 -> 86.439329
A38: 2024 | B38: ='Dados gerais'!T3 -> 45292 | C38: janeiro | D38: =RANDBETWEEN(181200,344400) -> 230197 | E38: ='Dados gerais'!W3 -> 250 | F38: ='Dados gerais'!V3 -> 3041 | G38: =D38/E38 -> 920.788 | H38: =D38/F38 -> 75.697797
A39: 2024 | B39: ='Dados gerais'!T4 -> 45323 | C39: fevereiro | D39: =RANDBETWEEN(181200,344400) -> 260575 | E39: ='Dados gerais'!W4 -> 249 | F39: ='Dados gerais'!V4 -> 3041 | G39: =D39/E39 -> 1046.4859 | H39: =D39/F39 -> 85.687274
A40: 2024 | B40: ='Dados gerais'!T5 -> 45352 | C40: março | D40: =RANDBETWEEN(181200,344400) -> 261363 | E40: ='Dados gerais'!W5 -> 250 | F40: ='Dados gerais'!V5 -> 3041 | G40: =D40/E40 -> 1045.452 | H40: =D40/F40 -> 85.946399
...

Sheet Energia elétrica
A1: Ano | B1: Data | C1: Mês | D1: Valor | E1: Consumo total em KWh | F1: Qte colaboradores | G1: Qte KWh por colaborador | H1: Qte metros quadrados | I1: Qte KWh por metro quadrado
A2: 2021 | B2: ='Dados gerais'!B3 -> 44197 | C2: =TEXT(B2,"mmmm") -> janeiro | D2: =(29808.75+36197.67)*60% -> 39603.852 | E2: =RANDBETWEEN(72000,125000) -> 108931 | F2: ='Dados gerais'!E3 -> 200 | G2: =E2/F2 -> 544.655 | H2: ='Dados gerais'!D3 -> 3041 | I2: =E2/H2 -> 35.820783
A3: 2021 | B3: ='Dados gerais'!B4 -> 44228 | C3: =TEXT(B3,"mmmm") -> fevereiro | D3: =(31190.46+27524.37)*60% -> 35228.898 | E3: =RANDBETWEEN(72000,125000) -> 75864 | F3: ='Dados gerais'!E4 -> 200 | G3: =E3/F3 -> 379.32 | H3: ='Dados gerais'!D4 -> 3041 | I3: =E3/H3 -> 24.947057
A4: 2021 | B4: ='Dados gerais'!B5 -> 44256 | C4: =TEXT(B4,"mmmm") -> março | D4: =(30018.95+26452.57)*60% -> 33882.912 | E4: =RANDBETWEEN(72000,125000) -> 114293 | F4: ='Dados gerais'!E5 -> 201 | G4: =E4/F4 -> 568.62189 | H4: ='Dados gerais'!D5 -> 3041 | I4: =E4/H4 -> 37.584018
A5: 2021 | B5: ='Dados gerais'!B6 -> 44287 | C5: =TEXT(B5,"mmmm") -> abril | D5: =(25546.88+29536.39)*60% -> 33049.962 | E5: =RANDBETWEEN(72000,125000) -> 73131 | F5: ='Dados gerais'!E6 -> 204 | G5: =E5/F5 -> 358.48529 | H5: ='Dados gerais'!D6 -> 3041 | I5: =E5/H5 -> 24.048339
A6: 2021 | B6: ='Dados gerais'!B7 -> 44317 | C6: =TEXT(B6,"mmmm") -> maio | D6: =(27943.79+30848.32)*60% -> 35275.266 | E6: =RANDBETWEEN(72000,125000) -> 121337 | F6: ='Dados gerais'!E7 -> 199 | G6: =E6/F6 -> 609.73367 | H6: ='Dados gerais'!D7 -> 3041 | I6: =E6/H6 -> 39.900362
A7: 2021 | B7: ='Dados gerais'!B8 -> 44348 | C7: =TEXT(B7,"mmmm") -> junho | D7: =(24738.42+27988.87)*60% -> 31636.374 | E7: =RANDBETWEEN(72000,125000) -> 117648 | F7: ='Dados gerais'!E8 -> 208 | G7: =E7/F7 -> 565.61538 | H7: ='Dados gerais'!D8 -> 3041 | I7: =E7/H7 -> 38.687274 | AF7: É o mês da Referência = 02/2024
A8: 2021 | B8: ='Dados gerais'!B9 -> 44378 | C8: =TEXT(B8,"mmmm") -> julho | D8: =(23828.05+26808)*60% -> 30381.63 | E8: =RANDBETWEEN(72000,125000) -> 110715 | F8: ='Dados gerais'!E9 -> 209 | G8: =E8/F8 -> 529.73684 | H8: ='Dados gerais'!D9 -> 3041 | I8: =E8/H8 -> 36.407432
A9: 2021 | B9: ='Dados gerais'!B10 -> 44409 | C9: =TEXT(B9,"mmmm") -> agosto | D9: =(23104.93+26357.78)*60% -> 29677.626 | E9: =RANDBETWEEN(72000,125000) -> 78823 | F9: ='Dados gerais'!E10 -> 203 | G9: =E9/F9 -> 388.29064 | H9: ='Dados gerais'!D10 -> 3041 | I9: =E9/H9 -> 25.920092
A10: 2021 | B10: ='Dados gerais'!B11 -> 44440 | C10: =TEXT(B10,"mmmm") -> setembro | D10: =(24300.33+27753.1)*60% -> 31232.058 | E10: =RANDBETWEEN(72000,125000) -> 110767 | F10: ='Dados gerais'!E11 -> 211 | G10: =E10/F10 -> 524.96209 | H10: ='Dados gerais'!D11 -> 3041 | I10: =E10/H10 -> 36.424531
A11: 2021 | B11: ='Dados gerais'!B12 -> 44470 | C11: =TEXT(B11,"mmmm") -> outubro | D11: =(25009.39+28541.73)*60% -> 32130.672 | E11: =RANDBETWEEN(72000,125000) -> 80731 | F11: ='Dados gerais'!E12 -> 219 | G11: =E11/F11 -> 368.6347 | H11: ='Dados gerais'!D12 -> 3041 | I11: =E11/H11 -> 26.547517
A12: 2021 | B12: ='Dados gerais'!B13 -> 44501 | C12: =TEXT(B12,"mmmm") -> novembro | D12: =(28412.53+32208.03)*60% -> 36372.336 | E12: =RANDBETWEEN(72000,125000) -> 111799 | F12: ='Dados gerais'!E13 -> 219 | G12: =E12/F12 -> 510.49772 | H12: ='Dados gerais'!D13 -> 3041 | I12: =E12/H12 -> 36.763893
A13: 2021 | B13: ='Dados gerais'!B14 -> 44531 | C13: =TEXT(B13,"mmmm") -> dezembro | D13: =(30323.17+25927.72)*60% -> 33750.534 | E13: =RANDBETWEEN(72000,125000) -> 98727 | F13: ='Dados gerais'!E14 -> 220 | G13: =E13/F13 -> 448.75909 | H13: ='Dados gerais'!D14 -> 3041 | I13: =E13/H13 -> 32.465307
A14: 2022 | B14: ='Dados gerais'!H3 -> 44562 | C14: =TEXT(B14,"mmmm") -> janeiro | D14: 40097.3 | E14: =RANDBETWEEN(72000,125000) -> 102928 | F14: ='Dados gerais'!K3 -> 222 | G14: =E14/F14 -> 463.63964 | H14: ='Dados gerais'!J3 -> 3041 | I14: =E14/H14 -> 33.846761
A15: 2022 | B15: ='Dados gerais'!H4 -> 44593 | C15: =TEXT(B15,"mmmm") -> fevereiro | D15: 34466.32 | E15: =RANDBETWEEN(72000,125000) -> 74315 | F15: ='Dados gerais'!K4 -> 220 | G15: =E15/F15 -> 337.79545 | H15: ='Dados gerais'!J4 -> 3041 | I15: =E15/H15 -> 24.437685
A16: 2022 | B16: ='Dados gerais'!H5 -> 44621 | C16: março | D16: 40107.36 | E16: =RANDBETWEEN(72000,125000) -> 91280 | F16: ='Dados gerais'!K5 -> 221 | G16: =E16/F16 -> 413.03167 | H16: ='Dados gerais'!J5 -> 3041 | I16: =E16/H16 -> 30.016442
A17: 2022 | B17: ='Dados gerais'!H6 -> 44652 | C17: abril | D17: 35625.14 | E17: =RANDBETWEEN(72000,125000) -> 94633 | F17: ='Dados gerais'!K6 -> 232 | G17: =E17/F17 -> 407.90086 | H17: ='Dados gerais'!J6 -> 3041 | I17: =E17/H17 -> 31.11904
A18: 2022 | B18: ='Dados gerais'!H7 -> 44682 | C18: maio | D18: 28028.72 | E18: =RANDBETWEEN(72000,125000) -> 110134 | F18: ='Dados gerais'!K7 -> 227 | G18: =E18/F18 -> 485.17181 | H18: ='Dados gerais'!J7 -> 3041 | I18: =E18/H18 -> 36.216376
A19: 2022 | B19: ='Dados gerais'!H8 -> 44713 | C19: junho | D19: 24345.492 | E19: =RANDBETWEEN(72000,125000) -> 116188 | F19: ='Dados gerais'!K8 -> 229 | G19: =E19/F19 -> 507.37118 | H19: ='Dados gerais'!J8 -> 3041 | I19: =E19/H19 -> 38.207169
A20: 2022 | B20: ='Dados gerais'!H9 -> 44743 | C20: julho | D20: 22727.136 | E20: =RANDBETWEEN(72000,125000) -> 112196 | F20: ='Dados gerais'!K9 -> 234 | G20: =E20/F20 -> 479.47009 | H20: ='Dados gerais'!J9 -> 3041 | I20: =E20/H20 -> 36.894443
A21: 2022 | B21: ='Dados gerais'!H10 -> 44774 | C21: agosto | D21: 22943.112 | E21: =RANDBETWEEN(72000,125000) -> 72910 | F21: ='Dados gerais'!K10 -> 229 | G21: =E21/F21 -> 318.38428 | H21: ='Dados gerais'!J10 -> 3041 | I21: =E21/H21 -> 23.975666
A22: 2022 | B22: ='Dados gerais'!H11 -> 44805 | C22: setembro | D22: 23574.336 | E22: =RANDBETWEEN(72000,125000) -> 107357 | F22: ='Dados gerais'!K11 -> 231 | G22: =E22/F22 -> 464.74892 | H22: ='Dados gerais'!J11 -> 3041 | I22: =E22/H22 -> 35.30319
A23: 2022 | B23: ='Dados gerais'!H12 -> 44835 | C23: outubro | D23: 23989.77 | E23: =RANDBETWEEN(72000,125000) -> 123869 | F23: ='Dados gerais'!K12 -> 231 | G23: =E23/F23 -> 536.22944 | H23: ='Dados gerais'!J12 -> 3041 | I23: =E23/H23 -> 40.732983
A24: 2022 | B24: ='Dados gerais'!H13 -> 44866 | C24: novembro | D24: 22801.386 | E24: =RANDBETWEEN(72000,125000) -> 90387 | F24: ='Dados gerais'!K13 -> 234 | G24: =E24/F24 -> 386.26923 | H24: ='Dados gerais'!J13 -> 3041 | I24: =E24/H24 -> 29.722789
A25: 2023 | B25: ='Dados gerais'!N3 -> 44927 | C25: =TEXT(B25,"mmmm") -> janeiro | D25: 23721.96 | E25: =RANDBETWEEN(72000,125000) -> 97126 | F25: ='Dados gerais'!Q3 -> 236 | G25: =E25/F25 -> 411.55085 | H25: ='Dados gerais'!P3 -> 3041 | I25: =E25/H25 -> 31.938836
A26: 2023 | B26: ='Dados gerais'!N4 -> 44958 | C26: =TEXT(B26,"mmmm") -> fevereiro | D26: 26155.326 | E26: =RANDBETWEEN(72000,125000) -> 95778 | F26: ='Dados gerais'!Q4 -> 230 | G26: =E26/F26 -> 416.42609 | H26: ='Dados gerais'!P4 -> 3041 | I26: =E26/H26 -> 31.495561
A27: 2023 | B27: ='Dados gerais'!N5 -> 44986 | C27: março | D27: 28441.128 | E27: =RANDBETWEEN(72000,125000) -> 85633 | F27: ='Dados gerais'!Q5 -> 234 | G27: =E27/F27 -> 365.95299 | H27: ='Dados gerais'!P5 -> 3041 | I27: =E27/H27 -> 28.159487
A28: 2023 | B28: ='Dados gerais'!N6 -> 45017 | C28: abril | D28: 24535.626 | E28: =RANDBETWEEN(72000,125000) -> 106778 | F28: ='Dados gerais'!Q6 -> 236 | G28: =E28/F28 -> 452.44915 | H28: ='Dados gerais'!P6 -> 3041 | I28: =E28/H28 -> 35.112792
A29: 2023 | B29: ='Dados gerais'!N7 -> 45047 | C29: maio | D29: 25421.784 | E29: =RANDBETWEEN(72000,125000) -> 88232 | F29: ='Dados gerais'!Q7 -> 237 | G29: =E29/F29 -> 372.28692 | H29: ='Dados gerais'!P7 -> 3041 | I29: =E29/H29 -> 29.01414
A30: 2023 | B30: ='Dados gerais'!N8 -> 45078 | C30: junho | D30: 20223 | E30: =RANDBETWEEN(72000,125000) -> 83651 | F30: ='Dados gerais'!Q8 -> 239 | G30: =E30/F30 -> 350.00418 | H30: ='Dados gerais'!P8 -> 3041 | I30: =E30/H30 -> 27.507728
A31: 2023 | B31: ='Dados gerais'!N9 -> 45108 | C31: julho | D31: 20354.52 | E31: =RANDBETWEEN(72000,125000) -> 123285 | F31: ='Dados gerais'!Q9 -> 248 | G31: =E31/F31 -> 497.11694 | H31: ='Dados gerais'!P9 -> 3041 | I31: =E31/H31 -> 40.54094
A32: 2023 | B32: ='Dados gerais'!N10 -> 45139 | C32: agosto | D32: 21738.384 | E32: =RANDBETWEEN(72000,125000) -> 102539 | F32: ='Dados gerais'!Q10 -> 248 | G32: =E32/F32 -> 413.46371 | H32: ='Dados gerais'!P10 -> 3041 | I32: =E32/H32 -> 33.718842
A33: 2023 | B33: ='Dados gerais'!N11 -> 45170 | C33: setembro | D33: 22209.882 | E33: =RANDBETWEEN(72000,125000) -> 101582 | F33: ='Dados gerais'!Q11 -> 248 | G33: =E33/F33 -> 409.60484 | H33: ='Dados gerais'!P11 -> 3041 | I33: =E33/H33 -> 33.404143
A34: 2023 | B34: ='Dados gerais'!N12 -> 45200 | C34: outubro | D34: =(24569.96+15079.99)*60% -> 23789.97 | E34: =RANDBETWEEN(72000,125000) -> 80837 | F34: ='Dados gerais'!Q12 -> 247 | G34: =E34/F34 -> 327.2753 | H34: ='Dados gerais'!P12 -> 3041 | I34: =E34/H34 -> 26.582374
A35: 2023 | B35: ='Dados gerais'!N13 -> 45231 | C35: novembro | D35: =(23833.32+14500.64)*60% -> 23000.376 | E35: =RANDBETWEEN(72000,125000) -> 122634 | F35: ='Dados gerais'!Q13 -> 246 | G35: =E35/F35 -> 498.5122 | H35: ='Dados gerais'!P13 -> 3041 | I35: =E35/H35 -> 40.326866
A36: 2023 | B36: ='Dados gerais'!N14 -> 45261 | C36: dezembro | D36: =(23540.2+14250.43)*60% -> 22674.378 | E36: =RANDBETWEEN(72000,125000) -> 114427 | F36: ='Dados gerais'!Q14 -> 243 | G36: =E36/F36 -> 470.893 | H36: ='Dados gerais'!P14 -> 3041 | I36: =E36/H36 -> 37.628083
A37: 2022 | B37: ='Dados gerais'!H14 -> 44896 | C37: dezembro | D37: 23721.96 | E37: =RANDBETWEEN(72000,125000) -> 97808 | F37: ='Dados gerais'!K14 -> 237 | G37: =E37/F37 -> 412.69198 | H37: ='Dados gerais'!J14 -> 3041 | I37: =E37/H37 -> 32.163104
A38: 2024 | B38: ='Dados gerais'!T3 -> 45292 | C38: =TEXT(B38,"mmmm") -> janeiro | D38: =(25633.98+16093.11)*60% -> 25036.254 | E38: =RANDBETWEEN(72000,125000) -> 77470 | F38: ='Dados gerais'!W3 -> 250 | G38: =E38/F38 -> 309.88 | H38: ='Dados gerais'!V3 -> 3041 | I38: =E38/H38 -> 25.475173
A39: 2024 | B39: ='Dados gerais'!T4 -> 45323 | C39: fevereiro | D39: =(24184.7+12065.47)*60% -> 21750.102 | E39: =RANDBETWEEN(72000,125000) -> 86811 | F39: ='Dados gerais'!W4 -> 249 | G39: =E39/F39 -> 348.63855 | H39: ='Dados gerais'!V4 -> 3041 | I39: =E39/H39 -> 28.54686
A40: 2024 | B40: ='Dados gerais'!T5 -> 45352 | C40: março | D40: =(25252.58+13356.35)*60% -> 23165.358 | E40: =RANDBETWEEN(72000,125000) -> 95372 | F40: ='Dados gerais'!W5 -> 250 | G40: =E40/F40 -> 381.488 | H40: ='Dados gerais'!V5 -> 3041 | I40: =E40/H40 -> 31.362052
...

Sheet Papel A4
A2: Ano | B2: Nome do mês | C2: Mês | D2: Quantidade de impressões | E2: Impressões em KG | F2: Qte colaboradores | G2: Qte impressões por colaboradores | H2: Qte Kg papel por colaboradores
A3: 2024 | B3: ='Dados gerais'!T3 -> 45292 | C3: janeiro | D3: 7999 | E3: =(D3*0.00468)/2 -> 18.71766 | F3: ='Dados gerais'!W3 -> 250 | G3: =D3/F3 -> 31.996 | H3: =E3/F3 -> 0.07487064
A4: 2024 | B4: ='Dados gerais'!T4 -> 45323 | C4: fevereiro | D4: 4203 | E4: =(D4*0.00468)/2 -> 9.83502 | F4: ='Dados gerais'!W4 -> 249 | G4: =D4/F4 -> 16.879518 | H4: =E4/F4 -> 0.039498072
A5: 2024 | B5: ='Dados gerais'!T5 -> 45352 | C5: março | D5: 5695 | E5: =(D5*0.00468)/2 -> 13.3263 | F5: ='Dados gerais'!W5 -> 250 | G5: =D5/F5 -> 22.78 | H5: =E5/F5 -> 0.0533052
A6: 2024 | B6: ='Dados gerais'!T6 -> 45383 | C6: abril | D6: 5432 | E6: =(D6*0.00468)/2 -> 12.71088 | F6: ='Dados gerais'!W6 -> 259 | G6: =D6/F6 -> 20.972973 | H6: =E6/F6 -> 0.049076757
A7: 2024 | B7: ='Dados gerais'!T7 -> 45413 | C7: maio | D7: 5080 | E7: =(D7*0.00468)/2 -> 11.8872 | F7: ='Dados gerais'!W7 -> 257 | G7: =D7/F7 -> 19.766537 | H7: =E7/F7 -> 0.046253696
A8: 2024 | B8: ='Dados gerais'!T8 -> 45444 | C8: junho | D8: 8157 | E8: =(D8*0.00468)/2 -> 19.08738 | F8: ='Dados gerais'!W8 -> 255 | G8: =D8/F8 -> 31.988235 | H8: =E8/F8 -> 0.074852471
A9: 2024 | B9: ='Dados gerais'!T9 -> 45474 | C9: julho | D9: =4667+1208 -> 5875 | E9: =(D9*0.00468)/2 -> 13.7475 | F9: ='Dados gerais'!W9 -> 262 | G9: =D9/F9 -> 22.423664 | H9: =E9/F9 -> 0.052471374
A10: 2024 | B10: ='Dados gerais'!T10 -> 45505 | C10: agosto | D10: =6674+11.21 -> 6685.21 | E10: =(D10*0.00468)/2 -> 15.643391 | F10: ='Dados gerais'!W10 -> 258 | G10: =D10/F10 -> 25.911667 | H10: =E10/F10 -> 0.0606333
A11: 2024 | B11: ='Dados gerais'!T11 -> 45536 | C11: setembro | D11: =5361+798 -> 6159 | E11: =(D11*0.00468)/2 -> 14.41206 | F11: ='Dados gerais'!W11 -> 258 | G11: =D11/F11 -> 23.872093 | H11: =E11/F11 -> 0.055860698
A12: 2024 | B12: ='Dados gerais'!T12 -> 45566 | C12: outubro | D12: =5118+1161 -> 6279 | E12: =(D12*0.00468)/2 -> 14.69286 | F12: ='Dados gerais'!W12 -> 264 | G12: =D12/F12 -> 23.784091 | H12: =E12/F12 -> 0.055654773
A13: 2023 | B13: ='Dados gerais'!N3 -> 44927 | C13: =TEXT(B13,"mmmm") -> janeiro | D13: 7109 | E13: =(D13*0.00468)/2 -> 16.63506 | F13: ='Dados gerais'!Q3 -> 236 | G13: =D13/F13 -> 30.122881 | H13: =E13/F13 -> 0.070487542
A14: 2023 | B14: ='Dados gerais'!N4 -> 44958 | C14: =TEXT(B14,"mmmm") -> fevereiro | D14: 4884 | E14: =(D14*0.00468)/2 -> 11.42856 | F14: ='Dados gerais'!Q4 -> 230 | G14: =D14/F14 -> 21.234783 | H14: =E14/F14 -> 0.049689391
A15: 2023 | B15: ='Dados gerais'!N5 -> 44986 | C15: =TEXT(B15,"mmmm") -> março | D15: 8181 | E15: =(D15*0.00468)/2 -> 19.14354 | F15: ='Dados gerais'!Q5 -> 234 | G15: =D15/F15 -> 34.961538 | H15: =E15/F15 -> 0.08181
A16: 2023 | B16: ='Dados gerais'!N6 -> 45017 | C16: =TEXT(B16,"mmmm") -> abril | D16: 5295 | E16: =(D16*0.00468)/2 -> 12.3903 | F16: ='Dados gerais'!Q6 -> 236 | G16: =D16/F16 -> 22.436441 | H16: =E16/F16 -> 0.052501271
A17: 2023 | B17: ='Dados gerais'!N7 -> 45047 | C17: =TEXT(B17,"mmmm") -> maio | D17: 6262 | E17: =(D17*0.00468)/2 -> 14.65308 | F17: ='Dados gerais'!Q7 -> 237 | G17: =D17/F17 -> 26.421941 | H17: =E17/F17 -> 0.061827342
A18: 2023 | B18: ='Dados gerais'!N8 -> 45078 | C18: =TEXT(B18,"mmmm") -> junho | D18: 6243 | E18: =(D18*0.00468)/2 -> 14.60862 | F18: ='Dados gerais'!Q8 -> 239 | G18: =D18/F18 -> 26.121339 | H18: =E18/F18 -> 0.061123933
A19: 2023 | B19: ='Dados gerais'!N9 -> 45108 | C19: =TEXT(B19,"mmmm") -> julho | D19: 6174 | E19: =(D19*0.00468)/2 -> 14.44716 | F19: ='Dados gerais'!Q9 -> 248 | G19: =D19/F19 -> 24.895161 | H19: =E19/F19 -> 0.058254677
A20: 2023 | B20: ='Dados gerais'!N10 -> 45139 | C20: agosto | D20: 7481 | E20: =(D20*0.00468)/2 -> 17.50554 | F20: ='Dados gerais'!Q10 -> 248 | G20: =D20/F20 -> 30.165323 | H20: =E20/F20 -> 0.070586855
A21: 2023 | B21: ='Dados gerais'!N11 -> 45170 | C21: setembro | D21: 6288 | E21: 14.71392 | F21: ='Dados gerais'!Q11 -> 248 | G21: =D21/F21 -> 25.354839 | H21: =E21/F21 -> 0.059330323
A22: 2023 | B22: ='Dados gerais'!N12 -> 45200 | C22: outubro | D22: 7842 | E22: =(D22*0.00468)/2 -> 18.35028 | F22: ='Dados gerais'!Q12 -> 247 | G22: =D22/F22 -> 31.748988 | H22: =E22/F22 -> 0.074292632 | O22: Ou seja, o que o Geraldo mandou no NF contratos em maio preenchemos a coluna de abril.
A23: 2023 | B23: ='Dados gerais'!N13 -> 45231 | C23: novembro | D23: 6462 | E23: =(D23*0.00468)/2 -> 15.12108 | F23: ='Dados gerais'!Q13 -> 246 | G23: =D23/F23 -> 26.268293 | H23: =E23/F23 -> 0.061467805
A24: 2022 | B24: ='Dados gerais'!H3 -> 44562 | C24: =TEXT(B24,"mmmm") -> janeiro | D24: 5245 | E24: =(D24*0.00468)/2 -> 12.2733 | F24: ='Dados gerais'!K3 -> 222 | G24: =D24/F24 -> 23.626126 | H24: =E24/F24 -> 0.055285135
A25: 2022 | B25: ='Dados gerais'!H4 -> 44593 | C25: =TEXT(B25,"mmmm") -> fevereiro | D25: =14204+2947 -> 17151 | E25: =(D25*0.00468)/2 -> 40.13334 | F25: ='Dados gerais'!K4 -> 220 | G25: =D25/F25 -> 77.959091 | H25: =E25/F25 -> 0.18242427
A26: 2022 | B26: ='Dados gerais'!H5 -> 44621 | C26: =TEXT(B26,"mmmm") -> março | D26: =16034+3183 -> 19217 | E26: =(D26*0.00468)/2 -> 44.96778 | F26: ='Dados gerais'!K5 -> 221 | G26: =D26/F26 -> 86.954751 | H26: =E26/F26 -> 0.20347412
A27: 2022 | B27: ='Dados gerais'!H6 -> 44652 | C27: =TEXT(B27,"mmmm") -> abril | D27: =9924+3859 -> 13783 | E27: =(D27*0.00468)/2 -> 32.25222 | F27: ='Dados gerais'!K6 -> 232 | G27: =D27/F27 -> 59.409483 | H27: =E27/F27 -> 0.13901819
A28: 2022 | B28: ='Dados gerais'!H7 -> 44682 | C28: =TEXT(B28,"mmmm") -> maio | D28: =10174+4582 -> 14756 | E28: =(D28*0.00468)/2 -> 34.52904 | F28: ='Dados gerais'!K7 -> 227 | G28: =D28/F28 -> 65.004405 | H28: =E28/F28 -> 0.15211031
A29: 2022 | B29: ='Dados gerais'!H8 -> 44713 | C29: =TEXT(B29,"mmmm") -> junho | D29: =5960+1790 -> 7750 | E29: =(D29*0.00468)/2 -> 18.135 | F29: ='Dados gerais'!K8 -> 229 | G29: =D29/F29 -> 33.842795 | H29: =E29/F29 -> 0.07919214
A30: 2022 | B30: ='Dados gerais'!H9 -> 44743 | C30: =TEXT(B30,"mmmm") -> julho | D30: =2923+591 -> 3514 | E30: =(D30*0.00468)/2 -> 8.22276 | F30: ='Dados gerais'!K9 -> 234 | G30: =D30/F30 -> 15.017094 | H30: =E30/F30 -> 0.03514
A31: 2022 | B31: ='Dados gerais'!H10 -> 44774 | C31: =TEXT(B31,"mmmm") -> agosto | D31: =3061+363 -> 3424 | E31: =(D31*0.00468)/2 -> 8.01216 | F31: ='Dados gerais'!K10 -> 229 | G31: =D31/F31 -> 14.951965 | H31: =E31/F31 -> 0.034987598
A32: 2022 | B32: ='Dados gerais'!H11 -> 44805 | C32: =TEXT(B32,"mmmm") -> setembro | D32: =5177+2544 -> 7721 | E32: =(D32*0.00468)/2 -> 18.06714 | F32: ='Dados gerais'!K11 -> 231 | G32: =D32/F32 -> 33.424242 | H32: =E32/F32 -> 0.078212727
A33: 2022 | B33: ='Dados gerais'!H12 -> 44835 | C33: =TEXT(B33,"mmmm") -> outubro | D33: =2863+1239 -> 4102 | E33: =(D33*0.00468)/2 -> 9.59868 | F33: ='Dados gerais'!K12 -> 231 | G33: =D33/F33 -> 17.757576 | H33: =E33/F33 -> 0.041552727
A34: 2022 | B34: ='Dados gerais'!H13 -> 44866 | C34: =TEXT(B34,"mmmm") -> novembro | D34: =4324+879 -> 5203 | E34: =(D34*0.00468)/2 -> 12.17502 | F34: ='Dados gerais'!K13 -> 234 | G34: =D34/F34 -> 22.235043 | H34: =E34/F34 -> 0.05203
A35: 2022 | B35: ='Dados gerais'!H14 -> 44896 | C35: =TEXT(B35,"mmmm") -> dezembro | D35: =4243+769 -> 5012 | E35: =(D35*0.00468)/2 -> 11.72808 | F35: ='Dados gerais'!K14 -> 237 | G35: =D35/F35 -> 21.147679 | H35: =E35/F35 -> 0.04948557
A36: 2023 | B36: ='Dados gerais'!N14 -> 45261 | C36: =TEXT(B36,"mmmm") -> dezembro | D36: =3389+1339 -> 4728 | E36: =(D36*0.00468)/2 -> 11.06352 | F36: ='Dados gerais'!Q26 -> 0 | G36: =D36/F36 -> #DIV/0! | H36: =E36/F36 -> #DIV/0!
A37: 2021 | B37: ='Dados gerais'!B3 -> 44197 | C37: =TEXT(B37,"mmmm") -> janeiro | D37: 17155 | E37: =(D37*0.00468)/2 -> 40.1427 | F37: ='Dados gerais'!E3 -> 200 | G37: =D37/F37 -> 85.775 | H37: =E37/F37 -> 0.2007135
A38: 2021 | B38: ='Dados gerais'!B4 -> 44228 | C38: =TEXT(B38,"mmmm") -> fevereiro | D38: 14178 | E38: =(D38*0.00468)/2 -> 33.17652 | F38: ='Dados gerais'!E4 -> 200 | G38: =D38/F38 -> 70.89 | H38: =E38/F38 -> 0.1658826
A39: 2021 | B39: ='Dados gerais'!B5 -> 44256 | C39: =TEXT(B39,"mmmm") -> março | D39: 16533 | E39: =(D39*0.00468)/2 -> 38.68722 | F39: ='Dados gerais'!E5 -> 201 | G39: =D39/F39 -> 82.253731 | H39: =E39/F39 -> 0.19247373
A40: 2021 | B40: ='Dados gerais'!B6 -> 44287 | C40: =TEXT(B40,"mmmm") -> abril | D40: 13276 | E40: =(D40*0.00468)/2 -> 31.06584 | F40: ='Dados gerais'!E6 -> 204 | G40: =D40/F40 -> 65.078431 | H40: =E40/F40 -> 0.15228353
A41: 2021 | B41: ='Dados gerais'!B7 -> 44317 | C41: =TEXT(B41,"mmmm") -> maio | D41: 15824 | E41: =(D41*0.00468)/2 -> 37.02816 | F41: ='Dados gerais'!E7 -> 199 | G41: =D41/F41 -> 79.517588 | H41: =E41/F41 -> 0.18607116
...

Sheet Emissão CO2 terrestre
A2: Ano | B2: Nome do mês | C2: Mês | D2: CO² terrestre liberado em KG | E2: Qte km rodado | F2: Qte kg CO2 para cada 100km rodado
A3: 2024 | B3: ='Dados gerais'!T3 -> 45292 | C3: janeiro | D3: 0.103 | E3: 1234 | F3: =D3/E3 -> 8.3468395e-05
A4: 2024 | B4: ='Dados gerais'!T4 -> 45323 | C4: fevereiro | D4: 0.377 | E4: 2925 | F4: =D4/E4 -> 0.00012888889
A5: 2024 | B5: ='Dados gerais'!T5 -> 45352 | C5: março | D5: 0.7 | E5: 8374 | F5: =D5/E5 -> 8.3592071e-05
A6: 2024 | B6: ='Dados gerais'!T6 -> 45383 | C6: abril | D6: =0.806+0.189 -> 0.995 | E6: 8292 | F6: =D6/E6 -> 0.00011999518
A7: 2024 | B7: ='Dados gerais'!T7 -> 45413 | C7: maio | D7: =0.155+0.717 -> 0.872 | E7: =746.02+8579.92 -> 9325.94 | F7: =D7/E7 -> 9.3502639e-05
A8: 2024 | B8: ='Dados gerais'!T8 -> 45444 | C8: junho | D8: =0.099+0.337 -> 0.436 | E8: 4748 | F8: =D8/E8 -> 9.1828138e-05
A9: 2024 | B9: ='Dados gerais'!T9 -> 45474 | C9: julho | D9: 0.269 | E9: 7369.1 | F9: =D9/E9 -> 3.6503779e-05
A10: 2024 | B10: ='Dados gerais'!T10 -> 45505 | C10: agosto | D10: =0.413+0.76 -> 1.173 | E10: 11086.4 | F10: =D10/E10 -> 0.00010580531
A11: 2024 | B11: ='Dados gerais'!T11 -> 45536 | C11: setembro | D11: 0.952 | E11: 9754 | F11: =D11/E11 -> 9.7600984e-05
A12: 2024 | B12: ='Dados gerais'!T12 -> 45566 | C12: outubro | D12: 0.906 | E12: 9140.5 | F12: =D12/E12 -> 9.9119304e-05
A13: 2024 | B13: ='Dados gerais'!T13 -> 45597 | C13: novembro | D13: 0.825 | E13: 8450 | F13: =D13/E13 -> 9.7633136e-05
A14: 2024 | B14: ='Dados gerais'!T14 -> 45627 | C14: dezembro | D14: 0.558 | E14: 6677 | F14: =D14/E14 -> 8.3570466e-05
A15: 2025 | B15: ='Dados gerais'!Z3 -> 45658 | C15: ='Dados gerais'!AA3 -> janeiro | D15: 0.882 | E15: 6782.2 | F15: =D15/E15 -> 0.0001300463
A16: 2025 | B16: ='Dados gerais'!Z4 -> 45689 | C16: ='Dados gerais'!AA4 -> fevereiro | D16: 0.961 | E16: 9926.1 | F16: =D16/E16 -> 9.6815466e-05
A17: 2025 | B17: ='Dados gerais'!Z5 -> 45717 | C17: ='Dados gerais'!AA5 -> março | D17: 0.805 | E17: 8468 | F17: =D17/E17 -> 9.5063769e-05
A18: 2025 | B18: ='Dados gerais'!Z6 -> 45748 | C18: ='Dados gerais'!AA6 -> abril | D18: 1.128 | E18: 10804 | F18: =D18/E18 -> 0.00010440578
A19: 2025 | B19: ='Dados gerais'!Z7 -> 45778 | C19: ='Dados gerais'!AA7 -> maio | D19: 1.014 | E19: 10617 | F19: =D19/E19 -> 9.5507205e-05
A20: 2025 | B20: ='Dados gerais'!Z8 -> 45809 | C20: ='Dados gerais'!AA8 -> junho | D20: 0.435 | E20: 4483 | F20: =D20/E20 -> 9.7033237e-05
A21: 2025 | B21: ='Dados gerais'!Z9 -> 45839 | C21: ='Dados gerais'!AA9 -> julho | D21: 1.405 | E21: 6596 | F21: =D21/E21 -> 0.00021300788
A22: 2025 | B22: ='Dados gerais'!Z10 -> 45870 | C22: ='Dados gerais'!AA10 -> agosto
A23: 2025 | B23: ='Dados gerais'!Z11 -> 45901 | C23: ='Dados gerais'!AA11 -> setembro
A24: 2025 | B24: ='Dados gerais'!Z12 -> 45931 | C24: ='Dados gerais'!AA12 -> outubro
A25: 2025 | B25: ='Dados gerais'!Z13 -> 45962 | C25: ='Dados gerais'!AA13 -> novembro
A26: 2025 | B26: ='Dados gerais'!Z14 -> 45992 | C26: ='Dados gerais'!AA14 -> dezembro

Sheet Emissão de CO² aereo
A1: Ano | B1: Nome do mês | C1: Mês | D1: CO² aéreo liberado em KG | E1: Qte Viajantes | F1: Qte kg CO2 por Viajante
A2: 2024 | B2: ='Dados gerais'!T3 -> 45292 | C2: janeiro | D2: 3751.7 | E2: 37 | F2: =D2/E2 -> 101.3973
A3: 2024 | B3: ='Dados gerais'!T4 -> 45323 | C3: fevereiro | D3: 2548.3 | E3: 18 | F3: =D3/E3 -> 141.57222
A4: 2024 | B4: ='Dados gerais'!T5 -> 45352 | C4: março | D4: 3769.8 | E4: 30 | F4: =D4/E4 -> 125.66
A5: 2024 | B5: ='Dados gerais'!T6 -> 45383 | C5: abril | D5: 5578.3 | E5: 45 | F5: =D5/E5 -> 123.96222
A6: 2024 | B6: ='Dados gerais'!T7 -> 45413 | C6: maio | D6: 5799.9 | E6: 51 | F6: =D6/E6 -> 113.72353
A7: 2024 | B7: ='Dados gerais'!T8 -> 45444 | C7: junho | D7: 3440.5 | E7: 33 | F7: =D7/E7 -> 104.25758
A8: 2024 | B8: ='Dados gerais'!T9 -> 45474 | C8: julho | D8: 3600.4 | E8: 36 | F8: =D8/E8 -> 100.01111
A9: 2024 | B9: ='Dados gerais'!T10 -> 45505 | C9: agosto | D9: 4771 | E9: 42 | F9: =D9/E9 -> 113.59524
A10: 2024 | B10: ='Dados gerais'!T11 -> 45536 | C10: setembro | D10: 3834 | E10: 51 | F10: =D10/E10 -> 75.176471
A11: 2024 | B11: ='Dados gerais'!T12 -> 45566 | C11: outubro | D11: 4198.3 | E11: 53 | F11: =D11/E11 -> 79.213208
A12: 2024 | B12: ='Dados gerais'!T13 -> 45597 | C12: novembro | D12: 2756.1 | E12: 20 | F12: =D12/E12 -> 137.805
A13: 2023 | B13: ='Dados gerais'!N3 -> 44927 | C13: =TEXT(B13,"mmmm") -> janeiro | D13: 4824.73 | E13: 71 | F13: =D13/E13 -> 67.953944
A14: 2023 | B14: ='Dados gerais'!N4 -> 44958 | C14: =TEXT(B14,"mmmm") -> fevereiro | D14: 2948.178 | E14: 111 | F14: =D14/E14 -> 26.560162
A15: 2023 | B15: ='Dados gerais'!N5 -> 44986 | C15: =TEXT(B15,"mmmm") -> março | D15: 9727.184 | E15: 141 | F15: =D15/E15 -> 68.987121
A16: 2023 | B16: ='Dados gerais'!N6 -> 45017 | C16: =TEXT(B16,"mmmm") -> abril | D16: 4955.032 | E16: 121 | F16: =D16/E16 -> 40.950678
A17: 2023 | B17: ='Dados gerais'!N7 -> 45047 | C17: =TEXT(B17,"mmmm") -> maio | D17: 6146.546 | E17: 105 | F17: =D17/E17 -> 58.538533
A18: 2023 | B18: ='Dados gerais'!N8 -> 45078 | C18: =TEXT(B18,"mmmm") -> junho | D18: 2578.1 | E18: 121 | F18: =D18/E18 -> 21.306612
A19: 2023 | B19: ='Dados gerais'!N9 -> 45108 | C19: julho | D19: 3100.324 | E19: 98 | F19: =D19/E19 -> 31.635959
A20: 2023 | B20: ='Dados gerais'!N10 -> 45139 | C20: agosto | D20: 6548.374 | E20: 139 | F20: =D20/E20 -> 47.110604
A21: 2023 | B21: ='Dados gerais'!N11 -> 45170 | C21: setembro | D21: 3212.338 | E21: 144 | F21: =D21/E21 -> 22.307903
A22: 2023 | B22: ='Dados gerais'!N12 -> 45200 | C22: outubro | D22: 3205.734 | E22: 28 | F22: =D22/E22 -> 114.4905
A23: 2023 | B23: ='Dados gerais'!N13 -> 45231 | C23: novembro | D23: 1981.246 | E23: 14 | F23: =D23/E23 -> 141.51757
A24: 2023 | B24: ='Dados gerais'!N14 -> 45261 | C24: dezembro | D24: 849.6 | E24: 11 | F24: =D24/E24 -> 77.236364
A25: 2022 | B25: ='Dados gerais'!H3 -> 44562 | C25: =TEXT(B25,"mmmm") -> janeiro | D25: 3268.85 | E25: 117 | F25: =D25/E25 -> 27.938889
A26: 2022 | B26: ='Dados gerais'!H4 -> 44593 | C26: =TEXT(B26,"mmmm") -> fevereiro | D26: 2093.51 | E26: 117 | F26: =D26/E26 -> 17.893248
A27: 2022 | B27: ='Dados gerais'!H5 -> 44621 | C27: =TEXT(B27,"mmmm") -> março | D27: 3603.74 | E27: 117 | F27: =D27/E27 -> 30.801197
A28: 2022 | B28: ='Dados gerais'!H6 -> 44652 | C28: =TEXT(B28,"mmmm") -> abril | D28: 2423.7 | E28: 117 | F28: =D28/E28 -> 20.715385
A29: 2022 | B29: ='Dados gerais'!H7 -> 44682 | C29: =TEXT(B29,"mmmm") -> maio | D29: 6080.91 | E29: 117 | F29: =D29/E29 -> 51.97359
A30: 2022 | B30: ='Dados gerais'!H8 -> 44713 | C30: =TEXT(B30,"mmmm") -> junho | D30: 4456.06 | E30: 117 | F30: =D30/E30 -> 38.085983
A31: 2022 | B31: ='Dados gerais'!H9 -> 44743 | C31: =TEXT(B31,"mmmm") -> julho | D31: 12782.93 | E31: 117 | F31: =D31/E31 -> 109.25581
A32: 2022 | B32: ='Dados gerais'!H10 -> 44774 | C32: =TEXT(B32,"mmmm") -> agosto | D32: 9828.33 | E32: 117 | F32: =D32/E32 -> 84.002821
A33: 2022 | B33: ='Dados gerais'!H11 -> 44805 | C33: =TEXT(B33,"mmmm") -> setembro | D33: 5925.66 | E33: 117 | F33: =D33/E33 -> 50.646667
A34: 2022 | B34: ='Dados gerais'!H12 -> 44835 | C34: =TEXT(B34,"mmmm") -> outubro | D34: 5610.79 | E34: 117 | F34: =D34/E34 -> 47.95547
A35: 2022 | B35: ='Dados gerais'!H13 -> 44866 | C35: =TEXT(B35,"mmmm") -> novembro | D35: 1469 | E35: 117 | F35: =D35/E35 -> 12.555556
A36: 2022 | B36: ='Dados gerais'!H14 -> 44896 | C36: =TEXT(B36,"mmmm") -> dezembro | D36: 4751.04 | E36: 117 | F36: =D36/E36 -> 40.607179
A37: 2021 | B37: ='Dados gerais'!B3 -> 44197 | C37: =TEXT(B37,"mmmm") -> janeiro | D37: 0 | E37: 117 | F37: =D37/E37 -> 0
A38: 2021 | B38: ='Dados gerais'!B4 -> 44228 | C38: =TEXT(B38,"mmmm") -> fevereiro | D38: 1441.82 | E38: 117 | F38: =D38/E38 -> 12.323248
A39: 2021 | B39: ='Dados gerais'!B5 -> 44256 | C39: =TEXT(B39,"mmmm") -> março | D39: 506.29 | E39: 117 | F39: =D39/E39 -> 4.327265
A40: 2021 | B40: ='Dados gerais'!B6 -> 44287 | C40: =TEXT(B40,"mmmm") -> abril | D40: 0 | E40: 117 | F40: =D40/E40 -> 0
...

Sheet Copo descartável
A2: Ano | B2: Qte KG copo descartavel | C2: Qte colaboradores | D2: Qte kg copos plastico por colaborador
A3: 2021 | B3: =21+13.125 -> 34.125 | C3: =AVERAGE('Dados gerais'!E3:E14) -> 207.75 | D3: =B3/C3 -> 0.16425993
A4: 2022 | B4: =31.5+43.75 -> 75.25 | C4: =AVERAGE('Dados gerais'!K3:K13) -> 228.18182 | D4: =B4/C4 -> 0.32978088
A5: 2023 | B5: =3.5+7+13.125+13.125 -> 36.75 | C5: =AVERAGE('Dados gerais'!Q3:Q14) -> 241 | D5: =B5/C5 -> 0.15248963
A6: 2024 | B6: 3.5 | C6: =AVERAGE('Dados gerais'!W3:W17) -> 477.84615 | D6: =B6/C6 -> 0.0073245332
A7: 2025 | C7: =AVERAGE('Dados gerais'!AC3:AC14) -> 291.66667

Sheet Qte residuos comum
A2: Ano | B2: Mês | C2: Qte KG residuo comum | D2: Qte colaboradores | E2: Qte kg residuo comum por colaborador
A3: 2023 | B3: ='Dados gerais'!N12 -> 45200 | C3: 197.23 | D3: ='Dados gerais'!Q12 -> 247 | E3: =C3/D3 -> 0.79850202
A4: 2023 | B4: ='Dados gerais'!N13 -> 45231 | C4: 453.16 | D4: ='Dados gerais'!Q13 -> 246 | E4: =C4/D4 -> 1.8421138
A5: 2023 | B5: ='Dados gerais'!N14 -> 45261 | C5: 501.3 | D5: ='Dados gerais'!Q14 -> 243 | E5: =C5/D5 -> 2.062963
A6: 2024 | B6: ='Dados gerais'!T3 -> 45292 | C6: 545.47 | D6: ='Dados gerais'!W3 -> 250 | E6: =C6/D6 -> 2.18188
A7: 2024 | B7: ='Dados gerais'!T4 -> 45323 | C7: 521.78 | D7: ='Dados gerais'!W4 -> 249 | E7: =C7/D7 -> 2.095502
A8: 2024 | B8: ='Dados gerais'!T5 -> 45352 | C8: 625.65 | D8: ='Dados gerais'!W5 -> 250 | E8: =C8/D8 -> 2.5026
A9: 2024 | B9: ='Dados gerais'!T6 -> 45383 | C9: 633.78 | D9: ='Dados gerais'!W6 -> 259 | E9: =C9/D9 -> 2.447027
A10: 2024 | B10: ='Dados gerais'!T7 -> 45413 | C10: 557.64 | D10: ='Dados gerais'!W7 -> 257 | E10: =C10/D10 -> 2.1698054
A11: 2024 | B11: ='Dados gerais'!T8 -> 45444 | C11: 557.64 | D11: ='Dados gerais'!W8 -> 255 | E11: =C11/D11 -> 2.1868235
A12: 2024 | B12: ='Dados gerais'!T9 -> 45474 | C12: 557.64 | D12: ='Dados gerais'!W9 -> 262 | E12: =C12/D12 -> 2.1283969
A13: 2024 | B13: ='Dados gerais'!T10 -> 45505 | C13: 604.58 | D13: ='Dados gerais'!W10 -> 258 | E13: =C13/D13 -> 2.3433333
A14: 2024 | B14: ='Dados gerais'!T11 -> 45536 | C14: 624.01 | D14: ='Dados gerais'!W11 -> 258 | E14: =C14/D14 -> 2.4186434
A15: 2024 | B15: ='Dados gerais'!T12 -> 45566 | C15: 590.5 | D15: ='Dados gerais'!W12 -> 264 | E15: =C15/D15 -> 2.2367424
A16: 2024 | B16: ='Dados gerais'!T13 -> 45597 | C16: 448.5 | D16: ='Dados gerais'!W13 -> 266 | E16: =C16/D16 -> 1.6860902
A17: 2024 | B17: ='Dados gerais'!T14 -> 45627 | C17: 491.66 | D17: ='Dados gerais'!W14 -> 278 | E17: =C17/D17 -> 1.7685612
A18: 2025 | B18: ='Dados gerais'!Z3 -> 45658 | C18: 607.7 | D18: ='Dados gerais'!AC3 -> 287 | E18: =C18/D18 -> 2.1174216
A19: 2025 | B19: ='Dados gerais'!Z4 -> 45689 | C19: 559.35 | D19: ='Dados gerais'!AC4 -> 294 | E19: =C19/D19 -> 1.902551
A20: 2025 | B20: ='Dados gerais'!Z5 -> 45717 | C20: 489.63 | D20: ='Dados gerais'!AC5 -> 294 | E20: =C20/D20 -> 1.6654082
A21: 2025 | B21: ='Dados gerais'!Z6 -> 45748 | C21: 618.71 | D21: ='Dados gerais'!AC6 -> 0 | E21: =C21/D21 -> #DIV/0!
A22: 2025 | B22: ='Dados gerais'!Z7 -> 45778 | C22: 544.38 | D22: ='Dados gerais'!AC7 -> 0 | E22: =C22/D22 -> #DIV/0!
A23: 2025 | B23: ='Dados gerais'!Z8 -> 45809 | C23: 498.25 | D23: ='Dados gerais'!AC8 -> 0 | E23: =C23/D23 -> #DIV/0!
A24: 2025 | B24: ='Dados gerais'!Z9 -> 45839 | C24: 433.43 | D24: ='Dados gerais'!AC9 -> 0 | E24: =C24/D24 -> #DIV/0!
A25: 2025 | B25: ='Dados gerais'!Z10 -> 45870 | D25: ='Dados gerais'!AC10 -> 0
A26: 2025 | B26: ='Dados gerais'!Z11 -> 45901 | D26: ='Dados gerais'!AC11 -> 0
A27: 2025 | B27: ='Dados gerais'!Z12 -> 45931 | D27: ='Dados gerais'!AC12 -> 0
A28: 2025 | B28: ='Dados gerais'!Z13 -> 45962 | D28: ='Dados gerais'!AC13 -> 0
A29: 2025 | B29: ='Dados gerais'!Z14 -> 45992 | D29: ='Dados gerais'!AC14 -> 0

Sheet Qte residuos reciclados
A1: Ano | B1: Mês | C1: Qte kg Residuos reciclados | D1: Qte colaboradores | E1: Pilha | F1: Papelão e Papel | G1: Vidro | H1: Plástico | I1: Eletrônicos
A2: 2023 | B2: ='Dados gerais'!N3 -> 44927 | C2: 32 | D2: ='Dados gerais'!Q3 -> 236 | E2: 0 | F2: 0 | G2: 0 | H2: 0 | I2: 0
A3: 2023 | B3: ='Dados gerais'!N4 -> 44958 | C3: 34 | D3: ='Dados gerais'!Q4 -> 230 | E3: 0 | F3: 0 | G3: 0 | H3: 0 | I3: 0
A4: 2023 | B4: ='Dados gerais'!N5 -> 44986 | C4: 35 | D4: ='Dados gerais'!Q5 -> 234 | E4: 0 | F4: 0 | G4: 0 | H4: 0 | I4: 0
A5: 2023 | B5: ='Dados gerais'!N6 -> 45017 | C5: =26.5+32 -> 58.5 | D5: ='Dados gerais'!Q6 -> 236 | E5: 0 | F5: 0 | G5: 0 | H5: 0 | I5: 0
A6: 2023 | B6: ='Dados gerais'!N7 -> 45047 | C6: 35 | D6: ='Dados gerais'!Q7 -> 237 | E6: 0 | F6: 0 | G6: 0 | H6: 0 | I6: 0
A7: 2023 | B7: ='Dados gerais'!N8 -> 45078 | C7: 35 | D7: ='Dados gerais'!Q8 -> 239 | E7: 0 | F7: 0 | G7: 0 | H7: 0 | I7: 0
A8: 2023 | B8: ='Dados gerais'!N9 -> 45108 | C8: 35 | D8: ='Dados gerais'!Q9 -> 248 | E8: 0 | F8: 0 | G8: 0 | H8: 0 | I8: 0
A9: 2023 | B9: ='Dados gerais'!N10 -> 45139 | C9: 28 | D9: ='Dados gerais'!Q10 -> 248 | E9: 0 | F9: 0 | G9: 0 | H9: 0 | I9: 0
A10: 2023 | B10: ='Dados gerais'!N11 -> 45170 | C10: 28 | D10: ='Dados gerais'!Q11 -> 248 | E10: 0 | F10: 0 | G10: 0 | H10: 0 | I10: 0
A11: 2023 | B11: ='Dados gerais'!N12 -> 45200 | C11: =42+12 -> 54 | D11: ='Dados gerais'!Q12 -> 247 | E11: 0 | F11: 0 | G11: 0 | H11: 0 | I11: 0
A12: 2024 | B12: ='Dados gerais'!T3 -> 45292 | C12: 35 | D12: ='Dados gerais'!W3 -> 250 | E12: 0 | F12: 35 | G12: 0 | H12: 0 | I12: 0
A13: 2024 | B13: ='Dados gerais'!T4 -> 45323 | C13: 38 | D13: ='Dados gerais'!W4 -> 249 | E13: 0 | F13: 38 | G13: 0 | H13: 0 | I13: 0
A14: 2024 | B14: ='Dados gerais'!T5 -> 45352 | C14: 42 | D14: ='Dados gerais'!W5 -> 250 | E14: 0 | F14: 42 | G14: 0 | H14: 0 | I14: 0
A15: 2024 | B15: ='Dados gerais'!T6 -> 45383 | C15: 35 | D15: ='Dados gerais'!W6 -> 259 | E15: 0 | F15: 35 | G15: 0 | H15: 0 | I15: 0
A16: 2024 | B16: ='Dados gerais'!T7 -> 45413 | C16: 31 | D16: ='Dados gerais'!W7 -> 257 | E16: 0 | F16: 31 | G16: 0 | H16: 0 | I16: 0
A17: 2024 | B17: ='Dados gerais'!T8 -> 45444 | C17: 31 | D17: ='Dados gerais'!W8 -> 255 | E17: 0 | F17: 31 | G17: 0 | H17: 0 | I17: 0
A18: 2024 | B18: ='Dados gerais'!T9 -> 45474 | C18: 31 | D18: ='Dados gerais'!W9 -> 262 | E18: 0 | F18: 31 | G18: 0 | H18: 0 | I18: 0
A19: 2024 | B19: ='Dados gerais'!T10 -> 45505 | C19: 30 | D19: ='Dados gerais'!W10 -> 258 | E19: 0 | F19: 30 | G19: 0 | H19: 0 | I19: 0
A20: 2024 | B20: ='Dados gerais'!T11 -> 45536 | C20: 35 | D20: ='Dados gerais'!W11 -> 258 | E20: 0 | F20: 35 | G20: 0 | H20: 0 | I20: 0
A21: 2024 | B21: ='Dados gerais'!T12 -> 45566 | C21: 48 | D21: ='Dados gerais'!W12 -> 264 | E21: 0 | F21: 48 | G21: 0 | H21: 0 | I21: 0
A22: 2024 | B22: ='Dados gerais'!T13 -> 45597 | C22: 171.5 | D22: ='Dados gerais'!W13 -> 266 | E22: 19.5 | F22: 152 | G22: 0 | H22: 0 | I22: 0
A23: 2024 | B23: ='Dados gerais'!T14 -> 45627 | C23: 133 | D23: ='Dados gerais'!W14 -> 278 | E23: 0 | F23: 133 | G23: 0 | H23: 0 | I23: 0
A24: 2025 | B24: ='Dados gerais'!Z3 -> 45658 | C24: 0 | D24: ='Dados gerais'!AC3 -> 287 | E24: 0 | F24: 0 | G24: 0 | H24: 0 | I24: 0
A25: 2025 | B25: ='Dados gerais'!Z4 -> 45689 | C25: 65 | D25: ='Dados gerais'!AC4 -> 294 | E25: 0 | F25: 18 | G25: 41.5 | H25: 6 | I25: 0
A26: 2025 | B26: ='Dados gerais'!Z5 -> 45717 | C26: 129.5 | D26: ='Dados gerais'!AC5 -> 294 | E26: 0 | F26: 89 | G26: 15.5 | H26: 25 | I26: 0
A27: 2025 | B27: ='Dados gerais'!Z6 -> 45748 | C27: 15 | D27: ='Dados gerais'!AC6 -> 0 | E27: 0 | F27: 15 | G27: 0 | H27: 0 | I27: 0
A28: 2025 | B28: ='Dados gerais'!Z7 -> 45778 | C28: 331 | D28: ='Dados gerais'!AC7 -> 0 | E28: 0 | F28: 268 | G28: 0 | H28: 47 | I28: 16
A29: 2025 | B29: ='Dados gerais'!Z8 -> 45809 | C29: 91 | D29: ='Dados gerais'!AC8 -> 0 | E29: 0 | F29: 83 | G29: 8 | H29: 0 | I29: 0
A30: 2025 | B30: ='Dados gerais'!Z9 -> 45839 | C30: 0 | D30: ='Dados gerais'!AC9 -> 0 | E30: 0 | F30: 0 | G30: 0 | H30: 0 | I30: 0
A31: 2025 | B31: ='Dados gerais'!Z10 -> 45870 | D31: ='Dados gerais'!AC10 -> 0
A32: 2025 | B32: ='Dados gerais'!Z11 -> 45901 | D32: ='Dados gerais'!AC11 -> 0
A33: 2025 | B33: ='Dados gerais'!Z12 -> 45931 | D33: ='Dados gerais'!AC12 -> 0
A34: 2025 | B34: ='Dados gerais'!Z13 -> 45962 | D34: ='Dados gerais'!AC13 -> 0
A35: 2025 | B35: ='Dados gerais'!Z14 -> 45992 | D35: ='Dados gerais'!AC14 -> 0
A36: 2023 | B36: ='Dados gerais'!N13 -> 45231 | D36: ='Dados gerais'!Q37 -> 0
A37: 2023 | B37: ='Dados gerais'!N14 -> 45261 | D37: ='Dados gerais'!Q38 -> 0
